Workbook

Sheet Juez 01
A1: Evaluador
A2: Fecha | B2: 45967
A4: Coherencia | B4: El ítem mide alguna variable/categoría presente en el cuadro de congruencia metodológica
A5: Claridad | B5: El ítem es claro (no genera confusión o contradicciones)
A6: Escala | B6: El ítem puede ser respondido de acuerdo a la escala que presenta el instrumento
A7: Relevancia | B7: El ítem es relevante para cumplir con las preguntas y objetivos de investigación
D9: EVALUACIÓN
A10: CONTENIDO | D10: Inaceptable | E10: Deficiente | F10: Regular | G10: Bueno | H10: Excelente
A11: Ítem | B11: Criterios | C11: Observación | D11: 1 | E11: 2 | F11: 3 | G11: 4 | H11: 5 | I11: Subtotal | J11: Total Ítem
A12: 1 | B12: Coherencia | H12: 5 | I12: =SUM(D12:H12) -> 5
B13: Claridad | H13: 5 | I13: =SUM(D13:H13) -> 5
B14: Escala | H14: 5 | I14: =SUM(D14:H14) -> 5
B15: Relevancia | H15: 5 | I15: =SUM(D15:H15) -> 5 | J15: =SUM(I12:I15) -> 20
A16: =A12+1 -> 2 | B16: Coherencia | H16: 5 | I16: =SUM(D16:H16) -> 5
B17: Claridad | H17: 5 | I17: =SUM(D17:H17) -> 5
B18: Escala | H18: 5 | I18: =SUM(D18:H18) -> 5
B19: Relevancia | H19: 5 | I19: =SUM(D19:H19) -> 5 | J19: =SUM(I16:I19) -> 20
A20: =A16+1 -> 3 | B20: Coherencia | H20: 5 | I20: =SUM(D20:H20) -> 5
B21: Claridad | G21: 4 | I21: =SUM(D21:H21) -> 4
B22: Escala | H22: 5 | I22: =SUM(D22:H22) -> 5
B23: Relevancia | H23: 5 | I23: =SUM(D23:H23) -> 5 | J23: =SUM(I20:I23) -> 19
A24: =A20+1 -> 4 | B24: Coherencia | H24: 5 | I24: =SUM(D24:H24) -> 5
B25: Claridad | H25: 5 | I25: =SUM(D25:H25) -> 5
B26: Escala | H26: 5 | I26: =SUM(D26:H26) -> 5
B27: Relevancia | H27: 5 | I27: =SUM(D27:H27) -> 5 | J27: =SUM(I24:I27) -> 20
A28: =A24+1 -> 5 | B28: Coherencia | H28: 5 | I28: =SUM(D28:H28) -> 5
B29: Claridad | H29: 5 | I29: =SUM(D29:H29) -> 5
B30: Escala | H30: 5 | I30: =SUM(D30:H30) -> 5
B31: Relevancia | H31: 5 | I31: =SUM(D31:H31) -> 5 | J31: =SUM(I28:I31) -> 20
A32: =A28+1 -> 6 | B32: Coherencia | H32: 5 | I32: =SUM(D32:H32) -> 5
B33: Claridad | H33: 5 | I33: =SUM(D33:H33) -> 5
B34: Escala | H34: 5 | I34: =SUM(D34:H34) -> 5
B35: Relevancia | H35: 5 | I35: =SUM(D35:H35) -> 5 | J35: =SUM(I32:I35) -> 20
A36: =A32+1 -> 7 | B36: Coherencia | H36: 5 | I36: =SUM(D36:H36) -> 5
B37: Claridad | H37: 5 | I37: =SUM(D37:H37) -> 5
B38: Escala | H38: 5 | I38: =SUM(D38:H38) -> 5
B39: Relevancia | H39: 5 | I39: =SUM(D39:H39) -> 5 | J39: =SUM(I36:I39) -> 20
A40: =A36+1 -> 8 | B40: Coherencia | H40: 5 | I40: =SUM(D40:H40) -> 5
B41: Claridad | H41: 5 | I41: =SUM(D41:H41) -> 5
B42: Escala | H42: 5 | I42: =SUM(D42:H42) -> 5
...

Sheet Juez 02
A1: Evaluador
A2: Fecha | B2: 44146
A4: Coherencia | B4: El ítem mide alguna variable/categoría presente en el cuadro de congruencia metodológica
A5: Claridad | B5: El ítem es claro (no genera confusión o contradicciones)
A6: Escala | B6: El ítem puede ser respondido de acuerdo a la escala que presenta el instrumento
A7: Relevancia | B7: El ítem es relevante para cumplir con las preguntas y objetivos de investigación
D9: EVALUACIÓN
A10: CONTENIDO | D10: Inaceptable | E10: Deficiente | F10: Regular | G10: Bueno | H10: Excelente
A11: Ítem | B11: Criterios | C11: Observación | D11: 1 | E11: 2 | F11: 3 | G11: 4 | H11: 5 | I11: Subtotal | J11: Total Ítem
A12: 1 | B12: Coherencia | H12: 5 | I12: =SUM(D12:H12) -> 5
B13: Claridad | H13: 5 | I13: =SUM(D13:H13) -> 5
B14: Escala | H14: 5 | I14: =SUM(D14:H14) -> 5
B15: Relevancia | H15: 5 | I15: =SUM(D15:H15) -> 5 | J15: =SUM(I12:I15) -> 20
A16: =A12+1 -> 2 | B16: Coherencia | H16: 5 | I16: =SUM(D16:H16) -> 5
B17: Claridad | H17: 5 | I17: =SUM(D17:H17) -> 5
B18: Escala | H18: 5 | I18: =SUM(D18:H18) -> 5
B19: Relevancia | H19: 5 | I19: =SUM(D19:H19) -> 5 | J19: =SUM(I16:I19) -> 20
A20: =A16+1 -> 3 | B20: Coherencia | H20: 5 | I20: =SUM(D20:H20) -> 5
B21: Claridad | H21: 5 | I21: =SUM(D21:H21) -> 5
B22: Escala | H22: 5 | I22: =SUM(D22:H22) -> 5
B23: Relevancia | H23: 5 | I23: =SUM(D23:H23) -> 5 | J23: =SUM(I20:I23) -> 20
A24: =A20+1 -> 4 | B24: Coherencia | H24: 5 | I24: =SUM(D24:H24) -> 5
B25: Claridad | G25: 4 | I25: =SUM(D25:H25) -> 4
B26: Escala | H26: 5 | I26: =SUM(D26:H26) -> 5
B27: Relevancia | H27: 5 | I27: =SUM(D27:H27) -> 5 | J27: =SUM(I24:I27) -> 19
A28: =A24+1 -> 5 | B28: Coherencia | H28: 5 | I28: =SUM(D28:H28) -> 5
B29: Claridad | G29: 4 | I29: =SUM(D29:H29) -> 4
B30: Escala | H30: 5 | I30: =SUM(D30:H30) -> 5
B31: Relevancia | H31: 5 | I31: =SUM(D31:H31) -> 5 | J31: =SUM(I28:I31) -> 19
A32: =A28+1 -> 6 | B32: Coherencia | H32: 5 | I32: =SUM(D32:H32) -> 5
B33: Claridad | H33: 5 | I33: =SUM(D33:H33) -> 5
B34: Escala | H34: 5 | I34: =SUM(D34:H34) -> 5
B35: Relevancia | H35: 5 | I35: =SUM(D35:H35) -> 5 | J35: =SUM(I32:I35) -> 20
A36: =A32+1 -> 7 | B36: Coherencia | H36: 5 | I36: =SUM(D36:H36) -> 5
B37: Claridad | H37: 5 | I37: =SUM(D37:H37) -> 5
B38: Escala | H38: 5 | I38: =SUM(D38:H38) -> 5
B39: Relevancia | H39: 5 | I39: =SUM(D39:H39) -> 5 | J39: =SUM(I36:I39) -> 20
A40: =A36+1 -> 8 | B40: Coherencia | H40: 5 | I40: =SUM(D40:H40) -> 5
B41: Claridad | H41: 5 | I41: =SUM(D41:H41) -> 5
B42: Escala | H42: 5 | I42: =SUM(D42:H42) -> 5
...

Sheet Juez 03
A1: Evaluador
A2: Fecha | B2: 44146
A4: Coherencia | B4: El ítem mide alguna variable/categoría presente en el cuadro de congruencia metodológica
A5: Claridad | B5: El ítem es claro (no genera confusión o contradicciones)
A6: Escala | B6: El ítem puede ser respondido de acuerdo a la escala que presenta el instrumento
A7: Relevancia | B7: El ítem es relevante para cumplir con las preguntas y objetivos de investigación
D9: EVALUACIÓN
A10: CONTENIDO | D10: Inaceptable | E10: Deficiente | F10: Regular | G10: Bueno | H10: Excelente
A11: Ítem | B11: Criterios | C11: Observación | D11: 1 | E11: 2 | F11: 3 | G11: 4 | H11: 5 | I11: Subtotal | J11: Total Ítem
A12: 1 | B12: Coherencia | H12: 5 | I12: =SUM(D12:H12) -> 5
B13: Claridad | H13: 5 | I13: =SUM(D13:H13) -> 5
B14: Escala | H14: 5 | I14: =SUM(D14:H14) -> 5
B15: Relevancia | H15: 5 | I15: =SUM(D15:H15) -> 5 | J15: =SUM(I12:I15) -> 20
A16: =A12+1 -> 2 | B16: Coherencia | H16: 5 | I16: =SUM(D16:H16) -> 5
B17: Claridad | H17: 5 | I17: =SUM(D17:H17) -> 5
B18: Escala | H18: 5 | I18: =SUM(D18:H18) -> 5
B19: Relevancia | H19: 5 | I19: =SUM(D19:H19) -> 5 | J19: =SUM(I16:I19) -> 20
A20: =A16+1 -> 3 | B20: Coherencia | H20: 5 | I20: =SUM(D20:H20) -> 5
B21: Claridad | H21: 5 | I21: =SUM(D21:H21) -> 5
B22: Escala | H22: 5 | I22: =SUM(D22:H22) -> 5
B23: Relevancia | H23: 5 | I23: =SUM(D23:H23) -> 5 | J23: =SUM(I20:I23) -> 20
A24: =A20+1 -> 4 | B24: Coherencia | H24: 5 | I24: =SUM(D24:H24) -> 5
B25: Claridad | G25: 4 | I25: =SUM(D25:H25) -> 4
B26: Escala | H26: 5 | I26: =SUM(D26:H26) -> 5
B27: Relevancia | H27: 5 | I27: =SUM(D27:H27) -> 5 | J27: =SUM(I24:I27) -> 19
A28: =A24+1 -> 5 | B28: Coherencia | H28: 5 | I28: =SUM(D28:H28) -> 5
B29: Claridad | G29: 4 | I29: =SUM(D29:H29) -> 4
B30: Escala | H30: 5 | I30: =SUM(D30:H30) -> 5
B31: Relevancia | H31: 5 | I31: =SUM(D31:H31) -> 5 | J31: =SUM(I28:I31) -> 19
A32: =A28+1 -> 6 | B32: Coherencia | H32: 5 | I32: =SUM(D32:H32) -> 5
B33: Claridad | H33: 5 | I33: =SUM(D33:H33) -> 5
B34: Escala | H34: 5 | I34: =SUM(D34:H34) -> 5
B35: Relevancia | H35: 5 | I35: =SUM(D35:H35) -> 5 | J35: =SUM(I32:I35) -> 20
A36: =A32+1 -> 7 | B36: Coherencia | H36: 5 | I36: =SUM(D36:H36) -> 5
B37: Claridad | H37: 5 | I37: =SUM(D37:H37) -> 5
B38: Escala | H38: 5 | I38: =SUM(D38:H38) -> 5
B39: Relevancia | H39: 5 | I39: =SUM(D39:H39) -> 5 | J39: =SUM(I36:I39) -> 20
A40: =A36+1 -> 8 | B40: Coherencia | H40: 5 | I40: =SUM(D40:H40) -> 5
B41: Claridad | H41: 5 | I41: =SUM(D41:H41) -> 5
B42: Escala | H42: 5 | I42: =SUM(D42:H42) -> 5
...

Sheet Juez 04
A1: Evaluador
A2: Fecha | B2: 44146
A4: Coherencia | B4: El ítem mide alguna variable/categoría presente en el cuadro de congruencia metodológica
A5: Claridad | B5: El ítem es claro (no genera confusión o contradicciones)
A6: Escala | B6: El ítem puede ser respondido de acuerdo a la escala que presenta el instrumento
A7: Relevancia | B7: El ítem es relevante para cumplir con las preguntas y objetivos de investigación
D9: EVALUACIÓN
A10: CONTENIDO | D10: Inaceptable | E10: Deficiente | F10: Regular | G10: Bueno | H10: Excelente
A11: Ítem | B11: Criterios | C11: Observación | D11: 1 | E11: 2 | F11: 3 | G11: 4 | H11: 5 | I11: Subtotal | J11: Total Ítem
A12: 1 | B12: Coherencia | H12: 5 | I12: =SUM(D12:H12) -> 5
B13: Claridad | H13: 5 | I13: =SUM(D13:H13) -> 5
B14: Escala | H14: 5 | I14: =SUM(D14:H14) -> 5
B15: Relevancia | H15: 5 | I15: =SUM(D15:H15) -> 5 | J15: =SUM(I12:I15) -> 20
A16: =A12+1 -> 2 | B16: Coherencia | H16: 5 | I16: =SUM(D16:H16) -> 5
B17: Claridad | H17: 5 | I17: =SUM(D17:H17) -> 5
B18: Escala | H18: 5 | I18: =SUM(D18:H18) -> 5
B19: Relevancia | H19: 5 | I19: =SUM(D19:H19) -> 5 | J19: =SUM(I16:I19) -> 20
A20: =A16+1 -> 3 | B20: Coherencia | H20: 5 | I20: =SUM(D20:H20) -> 5
B21: Claridad | H21: 5 | I21: =SUM(D21:H21) -> 5
B22: Escala | H22: 5 | I22: =SUM(D22:H22) -> 5
B23: Relevancia | H23: 5 | I23: =SUM(D23:H23) -> 5 | J23: =SUM(I20:I23) -> 20
A24: =A20+1 -> 4 | B24: Coherencia | H24: 5 | I24: =SUM(D24:H24) -> 5
B25: Claridad | G25: 4 | I25: =SUM(D25:H25) -> 4
B26: Escala | H26: 5 | I26: =SUM(D26:H26) -> 5
B27: Relevancia | H27: 5 | I27: =SUM(D27:H27) -> 5 | J27: =SUM(I24:I27) -> 19
A28: =A24+1 -> 5 | B28: Coherencia | H28: 5 | I28: =SUM(D28:H28) -> 5
B29: Claridad | H29: 5 | I29: =SUM(D29:H29) -> 5
B30: Escala | H30: 5 | I30: =SUM(D30:H30) -> 5
B31: Relevancia | H31: 5 | I31: =SUM(D31:H31) -> 5 | J31: =SUM(I28:I31) -> 20
A32: =A28+1 -> 6 | B32: Coherencia | H32: 5 | I32: =SUM(D32:H32) -> 5
B33: Claridad | H33: 5 | I33: =SUM(D33:H33) -> 5
B34: Escala | H34: 5 | I34: =SUM(D34:H34) -> 5
B35: Relevancia | H35: 5 | I35: =SUM(D35:H35) -> 5 | J35: =SUM(I32:I35) -> 20
A36: =A32+1 -> 7 | B36: Coherencia | H36: 5 | I36: =SUM(D36:H36) -> 5
B37: Claridad | H37: 5 | I37: =SUM(D37:H37) -> 5
B38: Escala | H38: 5 | I38: =SUM(D38:H38) -> 5
B39: Relevancia | H39: 5 | I39: =SUM(D39:H39) -> 5 | J39: =SUM(I36:I39) -> 20
A40: =A36+1 -> 8 | B40: Coherencia | H40: 5 | I40: =SUM(D40:H40) -> 5
B41: Claridad | H41: 5 | I41: =SUM(D41:H41) -> 5
B42: Escala | H42: 5 | I42: =SUM(D42:H42) -> 5
...

Sheet CVC
B1: Jueces | F1: 4 | H1: 20
A2: Ítem | B2: Juez 01 | C2: Juez 02 | D2: Juez 03 | E2: Juez 04 | F2: Sx1 | G2: Mx | H2: CVCi | I2: Pei | J2: CVCtc
A3: Ítem 01 | B3: ='Juez 01'!J15 -> 20 | C3: ='Juez 02'!J15 -> 20 | D3: ='Juez 03'!J15 -> 20 | E3: ='Juez 04'!J15 -> 20 | F3: =SUM(B3:E3) -> 80 | G3: =F3/$H$1 -> 4 | H3: =G3/$F$1 -> 1 | I3: =(1/$F$1)^$F$1 -> 0.00390625 | J3: =H3-I3 -> 0.99609375
A4: Ítem 02 | B4: ='Juez 01'!J19 -> 20 | C4: ='Juez 02'!J19 -> 20 | D4: ='Juez 03'!J19 -> 20 | E4: ='Juez 04'!J19 -> 20 | F4: =SUM(B4:E4) -> 80 | G4: =F4/$H$1 -> 4 | H4: =G4/$F$1 -> 1 | I4: =(1/$F$1)^$F$1 -> 0.00390625 | J4: =H4-I4 -> 0.99609375
A5: Ítem 03 | B5: ='Juez 01'!J23 -> 19 | C5: ='Juez 02'!J23 -> 20 | D5: ='Juez 03'!J23 -> 20 | E5: ='Juez 04'!J23 -> 20 | F5: =SUM(B5:E5) -> 79 | G5: =F5/$H$1 -> 3.95 | H5: =G5/$F$1 -> 0.9875 | I5: =(1/$F$1)^$F$1 -> 0.00390625 | J5: =H5-I5 -> 0.98359375
A6: Ítem 04 | B6: ='Juez 01'!J27 -> 20 | C6: ='Juez 02'!J27 -> 19 | D6: ='Juez 03'!J27 -> 19 | E6: ='Juez 04'!J27 -> 19 | F6: =SUM(B6:E6) -> 77 | G6: =F6/$H$1 -> 3.85 | H6: =G6/$F$1 -> 0.9625 | I6: =(1/$F$1)^$F$1 -> 0.00390625 | J6: =H6-I6 -> 0.95859375
A7: Ítem 05 | B7: ='Juez 01'!J31 -> 20 | C7: ='Juez 02'!J31 -> 19 | D7: ='Juez 03'!J31 -> 19 | E7: ='Juez 04'!J31 -> 20 | F7: =SUM(B7:E7) -> 78 | G7: =F7/$H$1 -> 3.9 | H7: =G7/$F$1 -> 0.975 | I7: =(1/$F$1)^$F$1 -> 0.00390625 | J7: =H7-I7 -> 0.97109375
A8: Ítem 06 | B8: ='Juez 01'!J35 -> 20 | C8: ='Juez 02'!J35 -> 20 | D8: ='Juez 03'!J35 -> 20 | E8: ='Juez 04'!J35 -> 20 | F8: =SUM(B8:E8) -> 80 | G8: =F8/$H$1 -> 4 | H8: =G8/$F$1 -> 1 | I8: =(1/$F$1)^$F$1 -> 0.00390625 | J8: =H8-I8 -> 0.99609375
A9: Ítem 07 | B9: ='Juez 01'!J39 -> 20 | C9: ='Juez 02'!J39 -> 20 | D9: ='Juez 03'!J39 -> 20 | E9: ='Juez 04'!J39 -> 20 | F9: =SUM(B9:E9) -> 80 | G9: =F9/$H$1 -> 4 | H9: =G9/$F$1 -> 1 | I9: =(1/$F$1)^$F$1 -> 0.00390625 | J9: =H9-I9 -> 0.99609375
A10: Ítem 08 | B10: ='Juez 01'!J43 -> 20 | C10: ='Juez 02'!J43 -> 18 | D10: ='Juez 03'!J43 -> 18 | E10: ='Juez 04'!J43 -> 20 | F10: =SUM(B10:E10) -> 76 | G10: =F10/$H$1 -> 3.8 | H10: =G10/$F$1 -> 0.95 | I10: =(1/$F$1)^$F$1 -> 0.00390625 | J10: =H10-I10 -> 0.94609375
A11: Ítem 09 | B11: ='Juez 01'!J47 -> 20 | C11: ='Juez 02'!J47 -> 19 | D11: ='Juez 03'!J47 -> 19 | E11: ='Juez 04'!J47 -> 19 | F11: =SUM(B11:E11) -> 77 | G11: =F11/$H$1 -> 3.85 | H11: =G11/$F$1 -> 0.9625 | I11: =(1/$F$1)^$F$1 -> 0.00390625 | J11: =H11-I11 -> 0.95859375
A12: Ítem 10 | B12: ='Juez 01'!J51 -> 19 | C12: ='Juez 02'!J51 -> 18 | D12: ='Juez 03'!J51 -> 18 | E12: ='Juez 04'!J51 -> 20 | F12: =SUM(B12:E12) -> 75 | G12: =F12/$H$1 -> 3.75 | H12: =G12/$F$1 -> 0.9375 | I12: =(1/$F$1)^$F$1 -> 0.00390625 | J12: =H12-I12 -> 0.93359375
A13: Ítem 11 | B13: ='Juez 01'!J55 -> 20 | C13: ='Juez 02'!J55 -> 20 | D13: ='Juez 03'!J55 -> 18 | E13: ='Juez 04'!J55 -> 20 | F13: =SUM(B13:E13) -> 78 | G13: =F13/$H$1 -> 3.9 | H13: =G13/$F$1 -> 0.975 | I13: =(1/$F$1)^$F$1 -> 0.00390625 | J13: =H13-I13 -> 0.97109375
A14: Ítem 12 | B14: ='Juez 01'!J59 -> 20 | C14: ='Juez 02'!J59 -> 18 | D14: ='Juez 03'!J59 -> 20 | E14: ='Juez 04'!J59 -> 20 | F14: =SUM(B14:E14) -> 78 | G14: =F14/$H$1 -> 3.9 | H14: =G14/$F$1 -> 0.975 | I14: =(1/$F$1)^$F$1 -> 0.00390625 | J14: =H14-I14 -> 0.97109375
A15: Ítem 13 | B15: ='Juez 01'!J63 -> 19 | C15: ='Juez 02'!J63 -> 18 | D15: ='Juez 03'!J63 -> 18 | E15: ='Juez 04'!J63 -> 19 | F15: =SUM(B15:E15) -> 74 | G15: =F15/$H$1 -> 3.7 | H15: =G15/$F$1 -> 0.925 | I15: =(1/$F$1)^$F$1 -> 0.00390625 | J15: =H15-I15 -> 0.92109375
A16: Ítem 14 | B16: ='Juez 01'!J67 -> 20 | C16: ='Juez 02'!J67 -> 23 | D16: ='Juez 03'!J67 -> 18 | E16: ='Juez 04'!J67 -> 20 | F16: =SUM(B16:E16) -> 81 | G16: =F16/$H$1 -> 4.05 | H16: =G16/$F$1 -> 1.0125 | I16: =(1/$F$1)^$F$1 -> 0.00390625 | J16: =H16-I16 -> 1.0085937
A17: Ítem 15 | B17: ='Juez 01'!J71 -> 20 | C17: ='Juez 02'!J71 -> 20 | D17: ='Juez 03'!J71 -> 20 | E17: ='Juez 04'!J71 -> 20 | F17: =SUM(B17:E17) -> 80 | G17: =F17/$H$1 -> 4 | H17: =G17/$F$1 -> 1 | I17: =(1/$F$1)^$F$1 -> 0.00390625 | J17: =H17-I17 -> 0.99609375
A18: Ítem 16 | B18: ='Juez 01'!J75 -> 20 | C18: ='Juez 02'!J75 -> 19 | D18: ='Juez 03'!J75 -> 20 | E18: ='Juez 04'!J75 -> 20 | F18: =SUM(B18:E18) -> 79 | G18: =F18/$H$1 -> 3.95 | H18: =G18/$F$1 -> 0.9875 | I18: =(1/$F$1)^$F$1 -> 0.00390625 | J18: =H18-I18 -> 0.98359375
A19: Ítem 17 | B19: ='Juez 01'!J79 -> 19 | C19: ='Juez 02'!J79 -> 17 | D19: ='Juez 03'!J79 -> 20 | E19: ='Juez 04'!J79 -> 19 | F19: =SUM(B19:E19) -> 75 | G19: =F19/$H$1 -> 3.75 | H19: =G19/$F$1 -> 0.9375 | I19: =(1/$F$1)^$F$1 -> 0.00390625 | J19: =H19-I19 -> 0.93359375
A20: Ítem 18 | B20: ='Juez 01'!J83 -> 20 | C20: ='Juez 02'!J83 -> 18 | D20: ='Juez 03'!J83 -> 20 | E20: ='Juez 04'!J83 -> 20 | F20: =SUM(B20:E20) -> 78 | G20: =F20/$H$1 -> 3.9 | H20: =G20/$F$1 -> 0.975 | I20: =(1/$F$1)^$F$1 -> 0.00390625 | J20: =H20-I20 -> 0.97109375
A21: Ítem 19 | B21: ='Juez 01'!J87 -> 20 | C21: ='Juez 02'!J87 -> 19 | D21: ='Juez 03'!J87 -> 20 | E21: ='Juez 04'!J87 -> 20 | F21: =SUM(B21:E21) -> 79 | G21: =F21/$H$1 -> 3.95 | H21: =G21/$F$1 -> 0.9875 | I21: =(1/$F$1)^$F$1 -> 0.00390625 | J21: =H21-I21 -> 0.98359375
A22: Ítem 20 | B22: ='Juez 01'!J91 -> 20 | C22: ='Juez 02'!J91 -> 20 | D22: ='Juez 03'!J91 -> 20 | E22: ='Juez 04'!J91 -> 20 | F22: =SUM(B22:E22) -> 80 | G22: =F22/$H$1 -> 4 | H22: =G22/$F$1 -> 1 | I22: =(1/$F$1)^$F$1 -> 0.00390625 | J22: =H22-I22 -> 0.99609375
I23: CVCt | J23: =AVERAGE(J3:J17) -> 0.97359375
